Epoch 1/200000
RNN states ->  Tensor("model/rnn/zeros:0", shape=(5, 71), dtype=float32)
RNN call ->  (5, 71)
End RNN call
RNN states ->  Tensor("model/rnn/while/Placeholder_2:0", shape=(5, 71), dtype=float32)
RNN call ->  (5, 71)
End RNN call
S  (47, 71)  Pin  (10, 71)
Pout  (71, 71)
<class 'tensorflow.python.framework.ops.Tensor'>
y_true  (5, 71)  y_pred  (5, 71)
Vin  (5, 10)  Vbf  (5, 71)
S  (47, 71)  Pin  (10, 71)
Pout  (71, 71)
Traceback (most recent call last):
  File "/Users/sea/Projects/AMN/omic_amn_mm/Build_Model_AMN.py", line 365, in <module>
    reservoir, pred, stats, _ = train_evaluate_model(model, verbose=True)
  File "/Users/sea/Projects/AMN/omic_amn_mm/Library/Build_Model.py", line 1907, in train_evaluate_model
    train_model(param, X, Y, X, Y, verbose=verbose)
  File "/Users/sea/Projects/AMN/omic_amn_mm/Library/Build_Model.py", line 1850, in train_model
    history = Net.model.fit(Xtrain, Ytrain,
  File "/Users/sea/opt/anaconda3/envs/mlpp/lib/python3.10/site-packages/wandb/integration/keras/keras.py", line 174, in new_v2
    return old_v2(*args, **kwargs)
  File "/Users/sea/opt/anaconda3/envs/mlpp/lib/python3.10/site-packages/wandb/integration/keras/keras.py", line 174, in new_v2
    return old_v2(*args, **kwargs)
  File "/Users/sea/opt/anaconda3/envs/mlpp/lib/python3.10/site-packages/wandb/integration/keras/keras.py", line 174, in new_v2
    return old_v2(*args, **kwargs)
  File "/Users/sea/opt/anaconda3/envs/mlpp/lib/python3.10/site-packages/keras/utils/traceback_utils.py", line 70, in error_handler
    raise e.with_traceback(filtered_tb) from None
  File "/var/folders/s9/vvd64z5927gbj3663y621llr0000gq/T/__autograph_generated_filed1rr46l8.py", line 15, in tf__train_function
    retval_ = ag__.converted_call(ag__.ld(step_function), (ag__.ld(self), ag__.ld(iterator)), None, fscope)
  File "/var/folders/s9/vvd64z5927gbj3663y621llr0000gq/T/__autograph_generated_filepwwhx8cf.py", line 42, in tf__loss
    loss = ag__.converted_call(ag__.ld(compute_loss), (ag__.ld(y_true), ag__.ld(y_pred), ag__.ld(Vbf), ag__.ld(Vin), ag__.ld(S), ag__.ld(Pin), ag__.ld(Pout)), None, fscope)
  File "/var/folders/s9/vvd64z5927gbj3663y621llr0000gq/T/__autograph_generated_filewgzrgms2.py", line 23, in tf__compute_loss
    ag__.ld(print)(ag__.ld(abc))
NameError: in user code:
    File "/Users/sea/opt/anaconda3/envs/mlpp/lib/python3.10/site-packages/keras/engine/training.py", line 1249, in train_function  *
        return step_function(self, iterator)
    File "/Users/sea/Projects/AMN/omic_amn_mm/Library/Build_Model.py", line 440, in loss  *
        loss = compute_loss(y_true, y_pred, Vbf, Vin, S, Pin, Pout)
    File "/Users/sea/Projects/AMN/omic_amn_mm/Library/Build_Model.py", line 359, in compute_loss  *
        print(abc)
    NameError: name 'abc' is not defined
Traceback (most recent call last):
  File "/Users/sea/Projects/AMN/omic_amn_mm/Build_Model_AMN.py", line 365, in <module>
    reservoir, pred, stats, _ = train_evaluate_model(model, verbose=True)
  File "/Users/sea/Projects/AMN/omic_amn_mm/Library/Build_Model.py", line 1907, in train_evaluate_model
    train_model(param, X, Y, X, Y, verbose=verbose)
  File "/Users/sea/Projects/AMN/omic_amn_mm/Library/Build_Model.py", line 1850, in train_model
    history = Net.model.fit(Xtrain, Ytrain,
  File "/Users/sea/opt/anaconda3/envs/mlpp/lib/python3.10/site-packages/wandb/integration/keras/keras.py", line 174, in new_v2
    return old_v2(*args, **kwargs)
  File "/Users/sea/opt/anaconda3/envs/mlpp/lib/python3.10/site-packages/wandb/integration/keras/keras.py", line 174, in new_v2
    return old_v2(*args, **kwargs)
  File "/Users/sea/opt/anaconda3/envs/mlpp/lib/python3.10/site-packages/wandb/integration/keras/keras.py", line 174, in new_v2
    return old_v2(*args, **kwargs)
  File "/Users/sea/opt/anaconda3/envs/mlpp/lib/python3.10/site-packages/keras/utils/traceback_utils.py", line 70, in error_handler
    raise e.with_traceback(filtered_tb) from None
  File "/var/folders/s9/vvd64z5927gbj3663y621llr0000gq/T/__autograph_generated_filed1rr46l8.py", line 15, in tf__train_function
    retval_ = ag__.converted_call(ag__.ld(step_function), (ag__.ld(self), ag__.ld(iterator)), None, fscope)
  File "/var/folders/s9/vvd64z5927gbj3663y621llr0000gq/T/__autograph_generated_filepwwhx8cf.py", line 42, in tf__loss
    loss = ag__.converted_call(ag__.ld(compute_loss), (ag__.ld(y_true), ag__.ld(y_pred), ag__.ld(Vbf), ag__.ld(Vin), ag__.ld(S), ag__.ld(Pin), ag__.ld(Pout)), None, fscope)
  File "/var/folders/s9/vvd64z5927gbj3663y621llr0000gq/T/__autograph_generated_filewgzrgms2.py", line 23, in tf__compute_loss
    ag__.ld(print)(ag__.ld(abc))
NameError: in user code:
    File "/Users/sea/opt/anaconda3/envs/mlpp/lib/python3.10/site-packages/keras/engine/training.py", line 1249, in train_function  *
        return step_function(self, iterator)
    File "/Users/sea/Projects/AMN/omic_amn_mm/Library/Build_Model.py", line 440, in loss  *
        loss = compute_loss(y_true, y_pred, Vbf, Vin, S, Pin, Pout)
    File "/Users/sea/Projects/AMN/omic_amn_mm/Library/Build_Model.py", line 359, in compute_loss  *
        print(abc)
    NameError: name 'abc' is not defined